"GET / HTTP/1.1" 200 2386
"GET /%2Fupvote?id=4 HTTP/1.1" 200 1
C:\dev\py\web3\mysite\rethit\urls.py changed, reloading.
Watching for file changes with StatReloader
"GET / HTTP/1.1" 200 2383
"GET /upvote?id=4 HTTP/1.1" 200 1
"GET /upvote?id=4 HTTP/1.1" 200 1
"GET / HTTP/1.1" 200 2421
"GET /upvote?id=4 HTTP/1.1" 200 1
"GET /upvote?id=4 HTTP/1.1" 200 2
"GET /upvote?id=4 HTTP/1.1" 200 2
"GET /upvote?id=4 HTTP/1.1" 200 2
"GET / HTTP/1.1" 200 2393
"GET /upvote?id=4 HTTP/1.1" 200 2
"GET /upvote?id=4 HTTP/1.1" 200 2
"GET / HTTP/1.1" 200 2383
"GET /upvote?id=3 HTTP/1.1" 200 1
"GET /upvote?id=2 HTTP/1.1" 200 1
"GET /upvote?id=3 HTTP/1.1" 200 1
"GET / HTTP/1.1" 200 2345
"GET /upvote?id=1 HTTP/1.1" 200 1
"GET /upvote?id=2 HTTP/1.1" 200 1
C:\dev\py\web3\mysite\rethit\views.py changed, reloading.
Watching for file changes with StatReloader
Internal Server Error: /
Traceback (most recent call last):
  File "C:\dev\py\web3\lib\site-packages\django\core\handlers\exception.py", line 34, in inner
    response = get_response(request)
  File "C:\dev\py\web3\lib\site-packages\django\core\handlers\base.py", line 115, in _get_response
    response = self.process_exception_by_middleware(e, request)
  File "C:\dev\py\web3\lib\site-packages\django\core\handlers\base.py", line 113, in _get_response
    response = wrapped_callback(request, *callback_args, **callback_kwargs)
  File "C:\dev\py\web3\mysite\rethit\views.py", line 23, in index
    return render(request, 'rethit/index.html', context)
  File "C:\dev\py\web3\lib\site-packages\django\shortcuts.py", line 36, in render
    content = loader.render_to_string(template_name, context, request, using=using)
  File "C:\dev\py\web3\lib\site-packages\django\template\loader.py", line 62, in render_to_string
    return template.render(context, request)
  File "C:\dev\py\web3\lib\site-packages\django\template\backends\django.py", line 61, in render
    return self.template.render(context)
  File "C:\dev\py\web3\lib\site-packages\django\template\base.py", line 171, in render
    return self._render(context)
  File "C:\dev\py\web3\lib\site-packages\django\template\base.py", line 163, in _render
    return self.nodelist.render(context)
  File "C:\dev\py\web3\lib\site-packages\django\template\base.py", line 937, in render
    bit = node.render_annotated(context)
  File "C:\dev\py\web3\lib\site-packages\django\template\base.py", line 904, in render_annotated
    return self.render(context)
  File "C:\dev\py\web3\lib\site-packages\django\template\defaulttags.py", line 443, in render
    url = reverse(view_name, args=args, kwargs=kwargs, current_app=current_app)
  File "C:\dev\py\web3\lib\site-packages\django\urls\base.py", line 90, in reverse
    return iri_to_uri(resolver._reverse_with_prefix(view, prefix, *args, **kwargs))
  File "C:\dev\py\web3\lib\site-packages\django\urls\resolvers.py", line 668, in _reverse_with_prefix
    raise NoReverseMatch(msg)
django.urls.exceptions.NoReverseMatch: Reverse for 'downvote' not found. 'downvote' is not a valid view function or pattern name.
"GET / HTTP/1.1" 500 128677
Not Found: /favicon.ico
"GET /favicon.ico HTTP/1.1" 404 2301
C:\dev\py\web3\mysite\rethit\urls.py changed, reloading.
Watching for file changes with StatReloader
C:\dev\py\web3\mysite\rethit\urls.py changed, reloading.
Watching for file changes with StatReloader
C:\dev\py\web3\mysite\rethit\urls.py changed, reloading.
Watching for file changes with StatReloader
"GET / HTTP/1.1" 200 2752
Forbidden (CSRF token missing or incorrect.): /downvote
"POST /downvote HTTP/1.1" 403 2513
Forbidden (CSRF token missing or incorrect.): /downvote
"POST /downvote HTTP/1.1" 403 2513
Forbidden (CSRF token missing or incorrect.): /upvote
"POST /upvote HTTP/1.1" 403 2513
Forbidden (CSRF token missing or incorrect.): /upvote
"POST /upvote HTTP/1.1" 403 2513
Forbidden (CSRF token missing or incorrect.): /upvote
"POST /upvote HTTP/1.1" 403 2513
Forbidden (CSRF token missing or incorrect.): /upvote
"POST /upvote HTTP/1.1" 403 2513
Forbidden (CSRF token missing or incorrect.): /upvote
"POST /upvote HTTP/1.1" 403 2513
Forbidden (CSRF token missing or incorrect.): /upvote
"POST /upvote HTTP/1.1" 403 2513
Forbidden (CSRF token missing or incorrect.): /upvote
"POST /upvote HTTP/1.1" 403 2513
Forbidden (CSRF token missing or incorrect.): /upvote
"POST /upvote HTTP/1.1" 403 2513
Forbidden (CSRF token missing or incorrect.): /upvote
"POST /upvote HTTP/1.1" 403 2513
Forbidden (CSRF token missing or incorrect.): /upvote
"POST /upvote HTTP/1.1" 403 2513
Forbidden (CSRF token missing or incorrect.): /upvote
"POST /upvote HTTP/1.1" 403 2513
"GET / HTTP/1.1" 200 2750
Internal Server Error: /upvote
Traceback (most recent call last):
  File "C:\dev\py\web3\lib\site-packages\django\utils\datastructures.py", line 78, in __getitem__
    list_ = super().__getitem__(key)
KeyError: 'id'

During handling of the above exception, another exception occurred:

Traceback (most recent call last):
  File "C:\dev\py\web3\lib\site-packages\django\core\handlers\exception.py", line 34, in inner
    response = get_response(request)
  File "C:\dev\py\web3\lib\site-packages\django\core\handlers\base.py", line 115, in _get_response
    response = self.process_exception_by_middleware(e, request)
  File "C:\dev\py\web3\lib\site-packages\django\core\handlers\base.py", line 113, in _get_response
    response = wrapped_callback(request, *callback_args, **callback_kwargs)
  File "C:\dev\py\web3\mysite\rethit\views.py", line 26, in upvote
    post_id = int(request.POST['id'])
  File "C:\dev\py\web3\lib\site-packages\django\utils\datastructures.py", line 80, in __getitem__
    raise MultiValueDictKeyError(key)
django.utils.datastructures.MultiValueDictKeyError: 'id'
"GET /upvote?id=3 HTTP/1.1" 500 16319
Internal Server Error: /upvote
Traceback (most recent call last):
  File "C:\dev\py\web3\lib\site-packages\django\utils\datastructures.py", line 78, in __getitem__
    list_ = super().__getitem__(key)
KeyError: 'id'

During handling of the above exception, another exception occurred:

Traceback (most recent call last):
  File "C:\dev\py\web3\lib\site-packages\django\core\handlers\exception.py", line 34, in inner
    response = get_response(request)
  File "C:\dev\py\web3\lib\site-packages\django\core\handlers\base.py", line 115, in _get_response
    response = self.process_exception_by_middleware(e, request)
  File "C:\dev\py\web3\lib\site-packages\django\core\handlers\base.py", line 113, in _get_response
    response = wrapped_callback(request, *callback_args, **callback_kwargs)
  File "C:\dev\py\web3\mysite\rethit\views.py", line 26, in upvote
    post_id = int(request.POST['id'])
  File "C:\dev\py\web3\lib\site-packages\django\utils\datastructures.py", line 80, in __getitem__
    raise MultiValueDictKeyError(key)
django.utils.datastructures.MultiValueDictKeyError: 'id'
"GET /upvote?id=3 HTTP/1.1" 500 16319
Internal Server Error: /upvote
Traceback (most recent call last):
  File "C:\dev\py\web3\lib\site-packages\django\utils\datastructures.py", line 78, in __getitem__
    list_ = super().__getitem__(key)
KeyError: 'id'

During handling of the above exception, another exception occurred:

Traceback (most recent call last):
  File "C:\dev\py\web3\lib\site-packages\django\core\handlers\exception.py", line 34, in inner
    response = get_response(request)
  File "C:\dev\py\web3\lib\site-packages\django\core\handlers\base.py", line 115, in _get_response
    response = self.process_exception_by_middleware(e, request)
  File "C:\dev\py\web3\lib\site-packages\django\core\handlers\base.py", line 113, in _get_response
    response = wrapped_callback(request, *callback_args, **callback_kwargs)
  File "C:\dev\py\web3\mysite\rethit\views.py", line 26, in upvote
    post_id = int(request.POST['id'])
  File "C:\dev\py\web3\lib\site-packages\django\utils\datastructures.py", line 80, in __getitem__
    raise MultiValueDictKeyError(key)
django.utils.datastructures.MultiValueDictKeyError: 'id'
"GET /upvote?id=3 HTTP/1.1" 500 16319
Internal Server Error: /upvote
Traceback (most recent call last):
  File "C:\dev\py\web3\lib\site-packages\django\utils\datastructures.py", line 78, in __getitem__
    list_ = super().__getitem__(key)
KeyError: 'id'

During handling of the above exception, another exception occurred:

Traceback (most recent call last):
  File "C:\dev\py\web3\lib\site-packages\django\core\handlers\exception.py", line 34, in inner
    response = get_response(request)
  File "C:\dev\py\web3\lib\site-packages\django\core\handlers\base.py", line 115, in _get_response
    response = self.process_exception_by_middleware(e, request)
  File "C:\dev\py\web3\lib\site-packages\django\core\handlers\base.py", line 113, in _get_response
    response = wrapped_callback(request, *callback_args, **callback_kwargs)
  File "C:\dev\py\web3\mysite\rethit\views.py", line 26, in upvote
    post_id = int(request.POST['id'])
  File "C:\dev\py\web3\lib\site-packages\django\utils\datastructures.py", line 80, in __getitem__
    raise MultiValueDictKeyError(key)
django.utils.datastructures.MultiValueDictKeyError: 'id'
"GET /upvote?id=3 HTTP/1.1" 500 16319
Internal Server Error: /upvote
Traceback (most recent call last):
  File "C:\dev\py\web3\lib\site-packages\django\utils\datastructures.py", line 78, in __getitem__
    list_ = super().__getitem__(key)
KeyError: 'id'

During handling of the above exception, another exception occurred:

Traceback (most recent call last):
  File "C:\dev\py\web3\lib\site-packages\django\core\handlers\exception.py", line 34, in inner
    response = get_response(request)
  File "C:\dev\py\web3\lib\site-packages\django\core\handlers\base.py", line 115, in _get_response
    response = self.process_exception_by_middleware(e, request)
  File "C:\dev\py\web3\lib\site-packages\django\core\handlers\base.py", line 113, in _get_response
    response = wrapped_callback(request, *callback_args, **callback_kwargs)
  File "C:\dev\py\web3\mysite\rethit\views.py", line 26, in upvote
    post_id = int(request.POST['id'])
  File "C:\dev\py\web3\lib\site-packages\django\utils\datastructures.py", line 80, in __getitem__
    raise MultiValueDictKeyError(key)
django.utils.datastructures.MultiValueDictKeyError: 'id'
"GET /upvote?id=3 HTTP/1.1" 500 16319
Internal Server Error: /upvote
Traceback (most recent call last):
  File "C:\dev\py\web3\lib\site-packages\django\utils\datastructures.py", line 78, in __getitem__
    list_ = super().__getitem__(key)
KeyError: 'id'

During handling of the above exception, another exception occurred:

Traceback (most recent call last):
  File "C:\dev\py\web3\lib\site-packages\django\core\handlers\exception.py", line 34, in inner
    response = get_response(request)
  File "C:\dev\py\web3\lib\site-packages\django\core\handlers\base.py", line 115, in _get_response
    response = self.process_exception_by_middleware(e, request)
  File "C:\dev\py\web3\lib\site-packages\django\core\handlers\base.py", line 113, in _get_response
    response = wrapped_callback(request, *callback_args, **callback_kwargs)
  File "C:\dev\py\web3\mysite\rethit\views.py", line 26, in upvote
    post_id = int(request.POST['id'])
  File "C:\dev\py\web3\lib\site-packages\django\utils\datastructures.py", line 80, in __getitem__
    raise MultiValueDictKeyError(key)
django.utils.datastructures.MultiValueDictKeyError: 'id'
"GET /upvote?id=3 HTTP/1.1" 500 16319
Internal Server Error: /upvote
Traceback (most recent call last):
  File "C:\dev\py\web3\lib\site-packages\django\utils\datastructures.py", line 78, in __getitem__
    list_ = super().__getitem__(key)
KeyError: 'id'

During handling of the above exception, another exception occurred:

Traceback (most recent call last):
  File "C:\dev\py\web3\lib\site-packages\django\core\handlers\exception.py", line 34, in inner
    response = get_response(request)
  File "C:\dev\py\web3\lib\site-packages\django\core\handlers\base.py", line 115, in _get_response
    response = self.process_exception_by_middleware(e, request)
  File "C:\dev\py\web3\lib\site-packages\django\core\handlers\base.py", line 113, in _get_response
    response = wrapped_callback(request, *callback_args, **callback_kwargs)
  File "C:\dev\py\web3\mysite\rethit\views.py", line 26, in upvote
    post_id = int(request.POST['id'])
  File "C:\dev\py\web3\lib\site-packages\django\utils\datastructures.py", line 80, in __getitem__
    raise MultiValueDictKeyError(key)
django.utils.datastructures.MultiValueDictKeyError: 'id'
"GET /upvote?id=3 HTTP/1.1" 500 16319
Internal Server Error: /upvote
Traceback (most recent call last):
  File "C:\dev\py\web3\lib\site-packages\django\utils\datastructures.py", line 78, in __getitem__
    list_ = super().__getitem__(key)
KeyError: 'id'

During handling of the above exception, another exception occurred:

Traceback (most recent call last):
  File "C:\dev\py\web3\lib\site-packages\django\core\handlers\exception.py", line 34, in inner
    response = get_response(request)
  File "C:\dev\py\web3\lib\site-packages\django\core\handlers\base.py", line 115, in _get_response
    response = self.process_exception_by_middleware(e, request)
  File "C:\dev\py\web3\lib\site-packages\django\core\handlers\base.py", line 113, in _get_response
    response = wrapped_callback(request, *callback_args, **callback_kwargs)
  File "C:\dev\py\web3\mysite\rethit\views.py", line 26, in upvote
    post_id = int(request.POST['id'])
  File "C:\dev\py\web3\lib\site-packages\django\utils\datastructures.py", line 80, in __getitem__
    raise MultiValueDictKeyError(key)
django.utils.datastructures.MultiValueDictKeyError: 'id'
"GET /upvote?id=3 HTTP/1.1" 500 16319
Internal Server Error: /downvote
Traceback (most recent call last):
  File "C:\dev\py\web3\lib\site-packages\django\utils\datastructures.py", line 78, in __getitem__
    list_ = super().__getitem__(key)
KeyError: 'id'

During handling of the above exception, another exception occurred:

Traceback (most recent call last):
  File "C:\dev\py\web3\lib\site-packages\django\core\handlers\exception.py", line 34, in inner
    response = get_response(request)
  File "C:\dev\py\web3\lib\site-packages\django\core\handlers\base.py", line 115, in _get_response
    response = self.process_exception_by_middleware(e, request)
  File "C:\dev\py\web3\lib\site-packages\django\core\handlers\base.py", line 113, in _get_response
    response = wrapped_callback(request, *callback_args, **callback_kwargs)
  File "C:\dev\py\web3\mysite\rethit\views.py", line 31, in downvote
    post_id = int(request.POST['id'])
  File "C:\dev\py\web3\lib\site-packages\django\utils\datastructures.py", line 80, in __getitem__
    raise MultiValueDictKeyError(key)
django.utils.datastructures.MultiValueDictKeyError: 'id'
"GET /downvote?id=3 HTTP/1.1" 500 16329
Internal Server Error: /downvote
Traceback (most recent call last):
  File "C:\dev\py\web3\lib\site-packages\django\utils\datastructures.py", line 78, in __getitem__
    list_ = super().__getitem__(key)
KeyError: 'id'

During handling of the above exception, another exception occurred:

Traceback (most recent call last):
  File "C:\dev\py\web3\lib\site-packages\django\core\handlers\exception.py", line 34, in inner
    response = get_response(request)
  File "C:\dev\py\web3\lib\site-packages\django\core\handlers\base.py", line 115, in _get_response
    response = self.process_exception_by_middleware(e, request)
  File "C:\dev\py\web3\lib\site-packages\django\core\handlers\base.py", line 113, in _get_response
    response = wrapped_callback(request, *callback_args, **callback_kwargs)
  File "C:\dev\py\web3\mysite\rethit\views.py", line 31, in downvote
    post_id = int(request.POST['id'])
  File "C:\dev\py\web3\lib\site-packages\django\utils\datastructures.py", line 80, in __getitem__
    raise MultiValueDictKeyError(key)
django.utils.datastructures.MultiValueDictKeyError: 'id'
"GET /downvote?id=3 HTTP/1.1" 500 16329
Internal Server Error: /downvote
Traceback (most recent call last):
  File "C:\dev\py\web3\lib\site-packages\django\utils\datastructures.py", line 78, in __getitem__
    list_ = super().__getitem__(key)
KeyError: 'id'

During handling of the above exception, another exception occurred:

Traceback (most recent call last):
  File "C:\dev\py\web3\lib\site-packages\django\core\handlers\exception.py", line 34, in inner
    response = get_response(request)
  File "C:\dev\py\web3\lib\site-packages\django\core\handlers\base.py", line 115, in _get_response
    response = self.process_exception_by_middleware(e, request)
  File "C:\dev\py\web3\lib\site-packages\django\core\handlers\base.py", line 113, in _get_response
    response = wrapped_callback(request, *callback_args, **callback_kwargs)
  File "C:\dev\py\web3\mysite\rethit\views.py", line 31, in downvote
    post_id = int(request.POST['id'])
  File "C:\dev\py\web3\lib\site-packages\django\utils\datastructures.py", line 80, in __getitem__
    raise MultiValueDictKeyError(key)
django.utils.datastructures.MultiValueDictKeyError: 'id'
"GET /downvote?id=3 HTTP/1.1" 500 16329
Internal Server Error: /downvote
Traceback (most recent call last):
  File "C:\dev\py\web3\lib\site-packages\django\utils\datastructures.py", line 78, in __getitem__
    list_ = super().__getitem__(key)
KeyError: 'id'

During handling of the above exception, another exception occurred:

Traceback (most recent call last):
  File "C:\dev\py\web3\lib\site-packages\django\core\handlers\exception.py", line 34, in inner
    response = get_response(request)
  File "C:\dev\py\web3\lib\site-packages\django\core\handlers\base.py", line 115, in _get_response
    response = self.process_exception_by_middleware(e, request)
  File "C:\dev\py\web3\lib\site-packages\django\core\handlers\base.py", line 113, in _get_response
    response = wrapped_callback(request, *callback_args, **callback_kwargs)
  File "C:\dev\py\web3\mysite\rethit\views.py", line 31, in downvote
    post_id = int(request.POST['id'])
  File "C:\dev\py\web3\lib\site-packages\django\utils\datastructures.py", line 80, in __getitem__
    raise MultiValueDictKeyError(key)
django.utils.datastructures.MultiValueDictKeyError: 'id'
"GET /downvote?id=3 HTTP/1.1" 500 16329
Internal Server Error: /downvote
Traceback (most recent call last):
  File "C:\dev\py\web3\lib\site-packages\django\utils\datastructures.py", line 78, in __getitem__
    list_ = super().__getitem__(key)
KeyError: 'id'

During handling of the above exception, another exception occurred:

Traceback (most recent call last):
  File "C:\dev\py\web3\lib\site-packages\django\core\handlers\exception.py", line 34, in inner
    response = get_response(request)
  File "C:\dev\py\web3\lib\site-packages\django\core\handlers\base.py", line 115, in _get_response
    response = self.process_exception_by_middleware(e, request)
  File "C:\dev\py\web3\lib\site-packages\django\core\handlers\base.py", line 113, in _get_response
    response = wrapped_callback(request, *callback_args, **callback_kwargs)
  File "C:\dev\py\web3\mysite\rethit\views.py", line 31, in downvote
    post_id = int(request.POST['id'])
  File "C:\dev\py\web3\lib\site-packages\django\utils\datastructures.py", line 80, in __getitem__
    raise MultiValueDictKeyError(key)
django.utils.datastructures.MultiValueDictKeyError: 'id'
"GET /downvote?id=3 HTTP/1.1" 500 16329
Internal Server Error: /downvote
Traceback (most recent call last):
  File "C:\dev\py\web3\lib\site-packages\django\utils\datastructures.py", line 78, in __getitem__
    list_ = super().__getitem__(key)
KeyError: 'id'

During handling of the above exception, another exception occurred:

Traceback (most recent call last):
  File "C:\dev\py\web3\lib\site-packages\django\core\handlers\exception.py", line 34, in inner
    response = get_response(request)
  File "C:\dev\py\web3\lib\site-packages\django\core\handlers\base.py", line 115, in _get_response
    response = self.process_exception_by_middleware(e, request)
  File "C:\dev\py\web3\lib\site-packages\django\core\handlers\base.py", line 113, in _get_response
    response = wrapped_callback(request, *callback_args, **callback_kwargs)
  File "C:\dev\py\web3\mysite\rethit\views.py", line 31, in downvote
    post_id = int(request.POST['id'])
  File "C:\dev\py\web3\lib\site-packages\django\utils\datastructures.py", line 80, in __getitem__
    raise MultiValueDictKeyError(key)
django.utils.datastructures.MultiValueDictKeyError: 'id'
"GET /downvote?id=3 HTTP/1.1" 500 16329
Internal Server Error: /downvote
Traceback (most recent call last):
  File "C:\dev\py\web3\lib\site-packages\django\utils\datastructures.py", line 78, in __getitem__
    list_ = super().__getitem__(key)
KeyError: 'id'

During handling of the above exception, another exception occurred:

Traceback (most recent call last):
  File "C:\dev\py\web3\lib\site-packages\django\core\handlers\exception.py", line 34, in inner
    response = get_response(request)
  File "C:\dev\py\web3\lib\site-packages\django\core\handlers\base.py", line 115, in _get_response
    response = self.process_exception_by_middleware(e, request)
  File "C:\dev\py\web3\lib\site-packages\django\core\handlers\base.py", line 113, in _get_response
    response = wrapped_callback(request, *callback_args, **callback_kwargs)
  File "C:\dev\py\web3\mysite\rethit\views.py", line 31, in downvote
    post_id = int(request.POST['id'])
  File "C:\dev\py\web3\lib\site-packages\django\utils\datastructures.py", line 80, in __getitem__
    raise MultiValueDictKeyError(key)
django.utils.datastructures.MultiValueDictKeyError: 'id'
"GET /downvote?id=3 HTTP/1.1" 500 16329
Internal Server Error: /downvote
Traceback (most recent call last):
  File "C:\dev\py\web3\lib\site-packages\django\utils\datastructures.py", line 78, in __getitem__
    list_ = super().__getitem__(key)
KeyError: 'id'

During handling of the above exception, another exception occurred:

Traceback (most recent call last):
  File "C:\dev\py\web3\lib\site-packages\django\core\handlers\exception.py", line 34, in inner
    response = get_response(request)
  File "C:\dev\py\web3\lib\site-packages\django\core\handlers\base.py", line 115, in _get_response
    response = self.process_exception_by_middleware(e, request)
  File "C:\dev\py\web3\lib\site-packages\django\core\handlers\base.py", line 113, in _get_response
    response = wrapped_callback(request, *callback_args, **callback_kwargs)
  File "C:\dev\py\web3\mysite\rethit\views.py", line 31, in downvote
    post_id = int(request.POST['id'])
  File "C:\dev\py\web3\lib\site-packages\django\utils\datastructures.py", line 80, in __getitem__
    raise MultiValueDictKeyError(key)
django.utils.datastructures.MultiValueDictKeyError: 'id'
"GET /downvote?id=3 HTTP/1.1" 500 16329
"GET / HTTP/1.1" 200 2793
Internal Server Error: /upvote
Traceback (most recent call last):
  File "C:\dev\py\web3\lib\site-packages\django\utils\datastructures.py", line 78, in __getitem__
    list_ = super().__getitem__(key)
KeyError: 'id'

During handling of the above exception, another exception occurred:

Traceback (most recent call last):
  File "C:\dev\py\web3\lib\site-packages\django\core\handlers\exception.py", line 34, in inner
    response = get_response(request)
  File "C:\dev\py\web3\lib\site-packages\django\core\handlers\base.py", line 115, in _get_response
    response = self.process_exception_by_middleware(e, request)
  File "C:\dev\py\web3\lib\site-packages\django\core\handlers\base.py", line 113, in _get_response
    response = wrapped_callback(request, *callback_args, **callback_kwargs)
  File "C:\dev\py\web3\mysite\rethit\views.py", line 26, in upvote
    post_id = int(request.POST['id'])
  File "C:\dev\py\web3\lib\site-packages\django\utils\datastructures.py", line 80, in __getitem__
    raise MultiValueDictKeyError(key)
django.utils.datastructures.MultiValueDictKeyError: 'id'
"GET /upvote?id=3 HTTP/1.1" 500 16319
Internal Server Error: /upvote
Traceback (most recent call last):
  File "C:\dev\py\web3\lib\site-packages\django\utils\datastructures.py", line 78, in __getitem__
    list_ = super().__getitem__(key)
KeyError: 'id'

During handling of the above exception, another exception occurred:

Traceback (most recent call last):
  File "C:\dev\py\web3\lib\site-packages\django\core\handlers\exception.py", line 34, in inner
    response = get_response(request)
  File "C:\dev\py\web3\lib\site-packages\django\core\handlers\base.py", line 115, in _get_response
    response = self.process_exception_by_middleware(e, request)
  File "C:\dev\py\web3\lib\site-packages\django\core\handlers\base.py", line 113, in _get_response
    response = wrapped_callback(request, *callback_args, **callback_kwargs)
  File "C:\dev\py\web3\mysite\rethit\views.py", line 26, in upvote
    post_id = int(request.POST['id'])
  File "C:\dev\py\web3\lib\site-packages\django\utils\datastructures.py", line 80, in __getitem__
    raise MultiValueDictKeyError(key)
django.utils.datastructures.MultiValueDictKeyError: 'id'
"GET /upvote?id=3 HTTP/1.1" 500 16319
Internal Server Error: /upvote
Traceback (most recent call last):
  File "C:\dev\py\web3\lib\site-packages\django\utils\datastructures.py", line 78, in __getitem__
    list_ = super().__getitem__(key)
KeyError: 'id'

During handling of the above exception, another exception occurred:

Traceback (most recent call last):
  File "C:\dev\py\web3\lib\site-packages\django\core\handlers\exception.py", line 34, in inner
    response = get_response(request)
  File "C:\dev\py\web3\lib\site-packages\django\core\handlers\base.py", line 115, in _get_response
    response = self.process_exception_by_middleware(e, request)
  File "C:\dev\py\web3\lib\site-packages\django\core\handlers\base.py", line 113, in _get_response
    response = wrapped_callback(request, *callback_args, **callback_kwargs)
  File "C:\dev\py\web3\mysite\rethit\views.py", line 26, in upvote
    post_id = int(request.POST['id'])
  File "C:\dev\py\web3\lib\site-packages\django\utils\datastructures.py", line 80, in __getitem__
    raise MultiValueDictKeyError(key)
django.utils.datastructures.MultiValueDictKeyError: 'id'
"GET /upvote?id=3 HTTP/1.1" 500 16319
Internal Server Error: /upvote
Traceback (most recent call last):
  File "C:\dev\py\web3\lib\site-packages\django\utils\datastructures.py", line 78, in __getitem__
    list_ = super().__getitem__(key)
KeyError: 'id'

During handling of the above exception, another exception occurred:

Traceback (most recent call last):
  File "C:\dev\py\web3\lib\site-packages\django\core\handlers\exception.py", line 34, in inner
    response = get_response(request)
  File "C:\dev\py\web3\lib\site-packages\django\core\handlers\base.py", line 115, in _get_response
    response = self.process_exception_by_middleware(e, request)
  File "C:\dev\py\web3\lib\site-packages\django\core\handlers\base.py", line 113, in _get_response
    response = wrapped_callback(request, *callback_args, **callback_kwargs)
  File "C:\dev\py\web3\mysite\rethit\views.py", line 26, in upvote
    post_id = int(request.POST['id'])
  File "C:\dev\py\web3\lib\site-packages\django\utils\datastructures.py", line 80, in __getitem__
    raise MultiValueDictKeyError(key)
django.utils.datastructures.MultiValueDictKeyError: 'id'
"GET /upvote?id=3 HTTP/1.1" 500 16319
Internal Server Error: /upvote
Traceback (most recent call last):
  File "C:\dev\py\web3\lib\site-packages\django\utils\datastructures.py", line 78, in __getitem__
    list_ = super().__getitem__(key)
KeyError: 'id'

During handling of the above exception, another exception occurred:

Traceback (most recent call last):
  File "C:\dev\py\web3\lib\site-packages\django\core\handlers\exception.py", line 34, in inner
    response = get_response(request)
  File "C:\dev\py\web3\lib\site-packages\django\core\handlers\base.py", line 115, in _get_response
    response = self.process_exception_by_middleware(e, request)
  File "C:\dev\py\web3\lib\site-packages\django\core\handlers\base.py", line 113, in _get_response
    response = wrapped_callback(request, *callback_args, **callback_kwargs)
  File "C:\dev\py\web3\mysite\rethit\views.py", line 26, in upvote
    post_id = int(request.POST['id'])
  File "C:\dev\py\web3\lib\site-packages\django\utils\datastructures.py", line 80, in __getitem__
    raise MultiValueDictKeyError(key)
django.utils.datastructures.MultiValueDictKeyError: 'id'
"GET /upvote?id=3 HTTP/1.1" 500 16319
Internal Server Error: /upvote
Traceback (most recent call last):
  File "C:\dev\py\web3\lib\site-packages\django\utils\datastructures.py", line 78, in __getitem__
    list_ = super().__getitem__(key)
KeyError: 'id'

During handling of the above exception, another exception occurred:

Traceback (most recent call last):
  File "C:\dev\py\web3\lib\site-packages\django\core\handlers\exception.py", line 34, in inner
    response = get_response(request)
  File "C:\dev\py\web3\lib\site-packages\django\core\handlers\base.py", line 115, in _get_response
    response = self.process_exception_by_middleware(e, request)
  File "C:\dev\py\web3\lib\site-packages\django\core\handlers\base.py", line 113, in _get_response
    response = wrapped_callback(request, *callback_args, **callback_kwargs)
  File "C:\dev\py\web3\mysite\rethit\views.py", line 26, in upvote
    post_id = int(request.POST['id'])
  File "C:\dev\py\web3\lib\site-packages\django\utils\datastructures.py", line 80, in __getitem__
    raise MultiValueDictKeyError(key)
django.utils.datastructures.MultiValueDictKeyError: 'id'
"GET /upvote?id=3 HTTP/1.1" 500 16319
Internal Server Error: /upvote
Traceback (most recent call last):
  File "C:\dev\py\web3\lib\site-packages\django\utils\datastructures.py", line 78, in __getitem__
    list_ = super().__getitem__(key)
KeyError: 'id'

During handling of the above exception, another exception occurred:

Traceback (most recent call last):
  File "C:\dev\py\web3\lib\site-packages\django\core\handlers\exception.py", line 34, in inner
    response = get_response(request)
  File "C:\dev\py\web3\lib\site-packages\django\core\handlers\base.py", line 115, in _get_response
    response = self.process_exception_by_middleware(e, request)
  File "C:\dev\py\web3\lib\site-packages\django\core\handlers\base.py", line 113, in _get_response
    response = wrapped_callback(request, *callback_args, **callback_kwargs)
  File "C:\dev\py\web3\mysite\rethit\views.py", line 26, in upvote
    post_id = int(request.POST['id'])
  File "C:\dev\py\web3\lib\site-packages\django\utils\datastructures.py", line 80, in __getitem__
    raise MultiValueDictKeyError(key)
django.utils.datastructures.MultiValueDictKeyError: 'id'
"GET /upvote?id=3 HTTP/1.1" 500 16319
Internal Server Error: /upvote
Traceback (most recent call last):
  File "C:\dev\py\web3\lib\site-packages\django\utils\datastructures.py", line 78, in __getitem__
    list_ = super().__getitem__(key)
KeyError: 'id'

During handling of the above exception, another exception occurred:

Traceback (most recent call last):
  File "C:\dev\py\web3\lib\site-packages\django\core\handlers\exception.py", line 34, in inner
    response = get_response(request)
  File "C:\dev\py\web3\lib\site-packages\django\core\handlers\base.py", line 115, in _get_response
    response = self.process_exception_by_middleware(e, request)
  File "C:\dev\py\web3\lib\site-packages\django\core\handlers\base.py", line 113, in _get_response
    response = wrapped_callback(request, *callback_args, **callback_kwargs)
  File "C:\dev\py\web3\mysite\rethit\views.py", line 26, in upvote
    post_id = int(request.POST['id'])
  File "C:\dev\py\web3\lib\site-packages\django\utils\datastructures.py", line 80, in __getitem__
    raise MultiValueDictKeyError(key)
django.utils.datastructures.MultiValueDictKeyError: 'id'
"GET /upvote?id=3 HTTP/1.1" 500 16319
Internal Server Error: /upvote
Traceback (most recent call last):
  File "C:\dev\py\web3\lib\site-packages\django\utils\datastructures.py", line 78, in __getitem__
    list_ = super().__getitem__(key)
KeyError: 'id'

During handling of the above exception, another exception occurred:

Traceback (most recent call last):
  File "C:\dev\py\web3\lib\site-packages\django\core\handlers\exception.py", line 34, in inner
    response = get_response(request)
  File "C:\dev\py\web3\lib\site-packages\django\core\handlers\base.py", line 115, in _get_response
    response = self.process_exception_by_middleware(e, request)
  File "C:\dev\py\web3\lib\site-packages\django\core\handlers\base.py", line 113, in _get_response
    response = wrapped_callback(request, *callback_args, **callback_kwargs)
  File "C:\dev\py\web3\mysite\rethit\views.py", line 26, in upvote
    post_id = int(request.POST['id'])
  File "C:\dev\py\web3\lib\site-packages\django\utils\datastructures.py", line 80, in __getitem__
    raise MultiValueDictKeyError(key)
django.utils.datastructures.MultiValueDictKeyError: 'id'
"GET /upvote?id=3 HTTP/1.1" 500 16319
Internal Server Error: /upvote
Traceback (most recent call last):
  File "C:\dev\py\web3\lib\site-packages\django\utils\datastructures.py", line 78, in __getitem__
    list_ = super().__getitem__(key)
KeyError: 'id'

During handling of the above exception, another exception occurred:

Traceback (most recent call last):
  File "C:\dev\py\web3\lib\site-packages\django\core\handlers\exception.py", line 34, in inner
    response = get_response(request)
  File "C:\dev\py\web3\lib\site-packages\django\core\handlers\base.py", line 115, in _get_response
    response = self.process_exception_by_middleware(e, request)
  File "C:\dev\py\web3\lib\site-packages\django\core\handlers\base.py", line 113, in _get_response
    response = wrapped_callback(request, *callback_args, **callback_kwargs)
  File "C:\dev\py\web3\mysite\rethit\views.py", line 26, in upvote
    post_id = int(request.POST['id'])
  File "C:\dev\py\web3\lib\site-packages\django\utils\datastructures.py", line 80, in __getitem__
    raise MultiValueDictKeyError(key)
django.utils.datastructures.MultiValueDictKeyError: 'id'
"GET /upvote?id=3 HTTP/1.1" 500 16319
Internal Server Error: /upvote
Traceback (most recent call last):
  File "C:\dev\py\web3\lib\site-packages\django\utils\datastructures.py", line 78, in __getitem__
    list_ = super().__getitem__(key)
KeyError: 'id'

During handling of the above exception, another exception occurred:

Traceback (most recent call last):
  File "C:\dev\py\web3\lib\site-packages\django\core\handlers\exception.py", line 34, in inner
    response = get_response(request)
  File "C:\dev\py\web3\lib\site-packages\django\core\handlers\base.py", line 115, in _get_response
    response = self.process_exception_by_middleware(e, request)
  File "C:\dev\py\web3\lib\site-packages\django\core\handlers\base.py", line 113, in _get_response
    response = wrapped_callback(request, *callback_args, **callback_kwargs)
  File "C:\dev\py\web3\mysite\rethit\views.py", line 26, in upvote
    post_id = int(request.POST['id'])
  File "C:\dev\py\web3\lib\site-packages\django\utils\datastructures.py", line 80, in __getitem__
    raise MultiValueDictKeyError(key)
django.utils.datastructures.MultiValueDictKeyError: 'id'
"GET /upvote?id=3 HTTP/1.1" 500 16319
Internal Server Error: /upvote
Traceback (most recent call last):
  File "C:\dev\py\web3\lib\site-packages\django\utils\datastructures.py", line 78, in __getitem__
    list_ = super().__getitem__(key)
KeyError: 'id'

During handling of the above exception, another exception occurred:

Traceback (most recent call last):
  File "C:\dev\py\web3\lib\site-packages\django\core\handlers\exception.py", line 34, in inner
    response = get_response(request)
  File "C:\dev\py\web3\lib\site-packages\django\core\handlers\base.py", line 115, in _get_response
    response = self.process_exception_by_middleware(e, request)
  File "C:\dev\py\web3\lib\site-packages\django\core\handlers\base.py", line 113, in _get_response
    response = wrapped_callback(request, *callback_args, **callback_kwargs)
  File "C:\dev\py\web3\mysite\rethit\views.py", line 26, in upvote
    post_id = int(request.POST['id'])
  File "C:\dev\py\web3\lib\site-packages\django\utils\datastructures.py", line 80, in __getitem__
    raise MultiValueDictKeyError(key)
django.utils.datastructures.MultiValueDictKeyError: 'id'
"GET /upvote?id=3 HTTP/1.1" 500 16319
Internal Server Error: /upvote
Traceback (most recent call last):
  File "C:\dev\py\web3\lib\site-packages\django\utils\datastructures.py", line 78, in __getitem__
    list_ = super().__getitem__(key)
KeyError: 'id'

During handling of the above exception, another exception occurred:

Traceback (most recent call last):
  File "C:\dev\py\web3\lib\site-packages\django\core\handlers\exception.py", line 34, in inner
    response = get_response(request)
  File "C:\dev\py\web3\lib\site-packages\django\core\handlers\base.py", line 115, in _get_response
    response = self.process_exception_by_middleware(e, request)
  File "C:\dev\py\web3\lib\site-packages\django\core\handlers\base.py", line 113, in _get_response
    response = wrapped_callback(request, *callback_args, **callback_kwargs)
  File "C:\dev\py\web3\mysite\rethit\views.py", line 26, in upvote
    post_id = int(request.POST['id'])
  File "C:\dev\py\web3\lib\site-packages\django\utils\datastructures.py", line 80, in __getitem__
    raise MultiValueDictKeyError(key)
django.utils.datastructures.MultiValueDictKeyError: 'id'
"GET /upvote?id=3 HTTP/1.1" 500 16319
Internal Server Error: /upvote
Traceback (most recent call last):
  File "C:\dev\py\web3\lib\site-packages\django\utils\datastructures.py", line 78, in __getitem__
    list_ = super().__getitem__(key)
KeyError: 'id'

During handling of the above exception, another exception occurred:

Traceback (most recent call last):
  File "C:\dev\py\web3\lib\site-packages\django\core\handlers\exception.py", line 34, in inner
    response = get_response(request)
  File "C:\dev\py\web3\lib\site-packages\django\core\handlers\base.py", line 115, in _get_response
    response = self.process_exception_by_middleware(e, request)
  File "C:\dev\py\web3\lib\site-packages\django\core\handlers\base.py", line 113, in _get_response
    response = wrapped_callback(request, *callback_args, **callback_kwargs)
  File "C:\dev\py\web3\mysite\rethit\views.py", line 26, in upvote
    post_id = int(request.POST['id'])
  File "C:\dev\py\web3\lib\site-packages\django\utils\datastructures.py", line 80, in __getitem__
    raise MultiValueDictKeyError(key)
django.utils.datastructures.MultiValueDictKeyError: 'id'
"GET /upvote?id=2 HTTP/1.1" 500 16319
Internal Server Error: /upvote
Traceback (most recent call last):
  File "C:\dev\py\web3\lib\site-packages\django\utils\datastructures.py", line 78, in __getitem__
    list_ = super().__getitem__(key)
KeyError: 'id'

During handling of the above exception, another exception occurred:

Traceback (most recent call last):
  File "C:\dev\py\web3\lib\site-packages\django\core\handlers\exception.py", line 34, in inner
    response = get_response(request)
  File "C:\dev\py\web3\lib\site-packages\django\core\handlers\base.py", line 115, in _get_response
    response = self.process_exception_by_middleware(e, request)
  File "C:\dev\py\web3\lib\site-packages\django\core\handlers\base.py", line 113, in _get_response
    response = wrapped_callback(request, *callback_args, **callback_kwargs)
  File "C:\dev\py\web3\mysite\rethit\views.py", line 26, in upvote
    post_id = int(request.POST['id'])
  File "C:\dev\py\web3\lib\site-packages\django\utils\datastructures.py", line 80, in __getitem__
    raise MultiValueDictKeyError(key)
django.utils.datastructures.MultiValueDictKeyError: 'id'
"GET /upvote?id=1 HTTP/1.1" 500 16319
Internal Server Error: /upvote
Traceback (most recent call last):
  File "C:\dev\py\web3\lib\site-packages\django\utils\datastructures.py", line 78, in __getitem__
    list_ = super().__getitem__(key)
KeyError: 'id'

During handling of the above exception, another exception occurred:

Traceback (most recent call last):
  File "C:\dev\py\web3\lib\site-packages\django\core\handlers\exception.py", line 34, in inner
    response = get_response(request)
  File "C:\dev\py\web3\lib\site-packages\django\core\handlers\base.py", line 115, in _get_response
    response = self.process_exception_by_middleware(e, request)
  File "C:\dev\py\web3\lib\site-packages\django\core\handlers\base.py", line 113, in _get_response
    response = wrapped_callback(request, *callback_args, **callback_kwargs)
  File "C:\dev\py\web3\mysite\rethit\views.py", line 26, in upvote
    post_id = int(request.POST['id'])
  File "C:\dev\py\web3\lib\site-packages\django\utils\datastructures.py", line 80, in __getitem__
    raise MultiValueDictKeyError(key)
django.utils.datastructures.MultiValueDictKeyError: 'id'
"GET /upvote?id=1 HTTP/1.1" 500 16319
Internal Server Error: /upvote
Traceback (most recent call last):
  File "C:\dev\py\web3\lib\site-packages\django\utils\datastructures.py", line 78, in __getitem__
    list_ = super().__getitem__(key)
KeyError: 'id'

During handling of the above exception, another exception occurred:

Traceback (most recent call last):
  File "C:\dev\py\web3\lib\site-packages\django\core\handlers\exception.py", line 34, in inner
    response = get_response(request)
  File "C:\dev\py\web3\lib\site-packages\django\core\handlers\base.py", line 115, in _get_response
    response = self.process_exception_by_middleware(e, request)
  File "C:\dev\py\web3\lib\site-packages\django\core\handlers\base.py", line 113, in _get_response
    response = wrapped_callback(request, *callback_args, **callback_kwargs)
  File "C:\dev\py\web3\mysite\rethit\views.py", line 26, in upvote
    post_id = int(request.POST['id'])
  File "C:\dev\py\web3\lib\site-packages\django\utils\datastructures.py", line 80, in __getitem__
    raise MultiValueDictKeyError(key)
django.utils.datastructures.MultiValueDictKeyError: 'id'
"GET /upvote?id=1 HTTP/1.1" 500 16319
Internal Server Error: /downvote
Traceback (most recent call last):
  File "C:\dev\py\web3\lib\site-packages\django\utils\datastructures.py", line 78, in __getitem__
    list_ = super().__getitem__(key)
KeyError: 'id'

During handling of the above exception, another exception occurred:

Traceback (most recent call last):
  File "C:\dev\py\web3\lib\site-packages\django\core\handlers\exception.py", line 34, in inner
    response = get_response(request)
  File "C:\dev\py\web3\lib\site-packages\django\core\handlers\base.py", line 115, in _get_response
    response = self.process_exception_by_middleware(e, request)
  File "C:\dev\py\web3\lib\site-packages\django\core\handlers\base.py", line 113, in _get_response
    response = wrapped_callback(request, *callback_args, **callback_kwargs)
  File "C:\dev\py\web3\mysite\rethit\views.py", line 31, in downvote
    post_id = int(request.POST['id'])
  File "C:\dev\py\web3\lib\site-packages\django\utils\datastructures.py", line 80, in __getitem__
    raise MultiValueDictKeyError(key)
django.utils.datastructures.MultiValueDictKeyError: 'id'
"GET /downvote?id=1 HTTP/1.1" 500 16329
Internal Server Error: /downvote
Traceback (most recent call last):
  File "C:\dev\py\web3\lib\site-packages\django\utils\datastructures.py", line 78, in __getitem__
    list_ = super().__getitem__(key)
KeyError: 'id'

During handling of the above exception, another exception occurred:

Traceback (most recent call last):
  File "C:\dev\py\web3\lib\site-packages\django\core\handlers\exception.py", line 34, in inner
    response = get_response(request)
  File "C:\dev\py\web3\lib\site-packages\django\core\handlers\base.py", line 115, in _get_response
    response = self.process_exception_by_middleware(e, request)
  File "C:\dev\py\web3\lib\site-packages\django\core\handlers\base.py", line 113, in _get_response
    response = wrapped_callback(request, *callback_args, **callback_kwargs)
  File "C:\dev\py\web3\mysite\rethit\views.py", line 31, in downvote
    post_id = int(request.POST['id'])
  File "C:\dev\py\web3\lib\site-packages\django\utils\datastructures.py", line 80, in __getitem__
    raise MultiValueDictKeyError(key)
django.utils.datastructures.MultiValueDictKeyError: 'id'
"GET /downvote?id=2 HTTP/1.1" 500 16329
Internal Server Error: /downvote
Traceback (most recent call last):
  File "C:\dev\py\web3\lib\site-packages\django\utils\datastructures.py", line 78, in __getitem__
    list_ = super().__getitem__(key)
KeyError: 'id'

During handling of the above exception, another exception occurred:

Traceback (most recent call last):
  File "C:\dev\py\web3\lib\site-packages\django\core\handlers\exception.py", line 34, in inner
    response = get_response(request)
  File "C:\dev\py\web3\lib\site-packages\django\core\handlers\base.py", line 115, in _get_response
    response = self.process_exception_by_middleware(e, request)
  File "C:\dev\py\web3\lib\site-packages\django\core\handlers\base.py", line 113, in _get_response
    response = wrapped_callback(request, *callback_args, **callback_kwargs)
  File "C:\dev\py\web3\mysite\rethit\views.py", line 31, in downvote
    post_id = int(request.POST['id'])
  File "C:\dev\py\web3\lib\site-packages\django\utils\datastructures.py", line 80, in __getitem__
    raise MultiValueDictKeyError(key)
django.utils.datastructures.MultiValueDictKeyError: 'id'
"GET /downvote?id=3 HTTP/1.1" 500 16329
"GET / HTTP/1.1" 200 2810
Internal Server Error: /upvote
Traceback (most recent call last):
  File "C:\dev\py\web3\lib\site-packages\django\utils\datastructures.py", line 78, in __getitem__
    list_ = super().__getitem__(key)
KeyError: 'id'

During handling of the above exception, another exception occurred:

Traceback (most recent call last):
  File "C:\dev\py\web3\lib\site-packages\django\core\handlers\exception.py", line 34, in inner
    response = get_response(request)
  File "C:\dev\py\web3\lib\site-packages\django\core\handlers\base.py", line 115, in _get_response
    response = self.process_exception_by_middleware(e, request)
  File "C:\dev\py\web3\lib\site-packages\django\core\handlers\base.py", line 113, in _get_response
    response = wrapped_callback(request, *callback_args, **callback_kwargs)
  File "C:\dev\py\web3\mysite\rethit\views.py", line 26, in upvote
    post_id = int(request.POST['id'])
  File "C:\dev\py\web3\lib\site-packages\django\utils\datastructures.py", line 80, in __getitem__
    raise MultiValueDictKeyError(key)
django.utils.datastructures.MultiValueDictKeyError: 'id'
"GET /upvote?id=3 HTTP/1.1" 500 16319
Internal Server Error: /upvote
Traceback (most recent call last):
  File "C:\dev\py\web3\lib\site-packages\django\utils\datastructures.py", line 78, in __getitem__
    list_ = super().__getitem__(key)
KeyError: 'id'

During handling of the above exception, another exception occurred:

Traceback (most recent call last):
  File "C:\dev\py\web3\lib\site-packages\django\core\handlers\exception.py", line 34, in inner
    response = get_response(request)
  File "C:\dev\py\web3\lib\site-packages\django\core\handlers\base.py", line 115, in _get_response
    response = self.process_exception_by_middleware(e, request)
  File "C:\dev\py\web3\lib\site-packages\django\core\handlers\base.py", line 113, in _get_response
    response = wrapped_callback(request, *callback_args, **callback_kwargs)
  File "C:\dev\py\web3\mysite\rethit\views.py", line 26, in upvote
    post_id = int(request.POST['id'])
  File "C:\dev\py\web3\lib\site-packages\django\utils\datastructures.py", line 80, in __getitem__
    raise MultiValueDictKeyError(key)
django.utils.datastructures.MultiValueDictKeyError: 'id'
"GET /upvote?id=3 HTTP/1.1" 500 16319
Internal Server Error: /upvote
Traceback (most recent call last):
  File "C:\dev\py\web3\lib\site-packages\django\utils\datastructures.py", line 78, in __getitem__
    list_ = super().__getitem__(key)
KeyError: 'id'

During handling of the above exception, another exception occurred:

Traceback (most recent call last):
  File "C:\dev\py\web3\lib\site-packages\django\core\handlers\exception.py", line 34, in inner
    response = get_response(request)
  File "C:\dev\py\web3\lib\site-packages\django\core\handlers\base.py", line 115, in _get_response
    response = self.process_exception_by_middleware(e, request)
  File "C:\dev\py\web3\lib\site-packages\django\core\handlers\base.py", line 113, in _get_response
    response = wrapped_callback(request, *callback_args, **callback_kwargs)
  File "C:\dev\py\web3\mysite\rethit\views.py", line 26, in upvote
    post_id = int(request.POST['id'])
  File "C:\dev\py\web3\lib\site-packages\django\utils\datastructures.py", line 80, in __getitem__
    raise MultiValueDictKeyError(key)
django.utils.datastructures.MultiValueDictKeyError: 'id'
"GET /upvote?id=3 HTTP/1.1" 500 16319
Internal Server Error: /upvote
Traceback (most recent call last):
  File "C:\dev\py\web3\lib\site-packages\django\utils\datastructures.py", line 78, in __getitem__
    list_ = super().__getitem__(key)
KeyError: 'id'

During handling of the above exception, another exception occurred:

Traceback (most recent call last):
  File "C:\dev\py\web3\lib\site-packages\django\core\handlers\exception.py", line 34, in inner
    response = get_response(request)
  File "C:\dev\py\web3\lib\site-packages\django\core\handlers\base.py", line 115, in _get_response
    response = self.process_exception_by_middleware(e, request)
  File "C:\dev\py\web3\lib\site-packages\django\core\handlers\base.py", line 113, in _get_response
    response = wrapped_callback(request, *callback_args, **callback_kwargs)
  File "C:\dev\py\web3\mysite\rethit\views.py", line 26, in upvote
    post_id = int(request.POST['id'])
  File "C:\dev\py\web3\lib\site-packages\django\utils\datastructures.py", line 80, in __getitem__
    raise MultiValueDictKeyError(key)
django.utils.datastructures.MultiValueDictKeyError: 'id'
"GET /upvote?id=2 HTTP/1.1" 500 16319
Internal Server Error: /upvote
Traceback (most recent call last):
  File "C:\dev\py\web3\lib\site-packages\django\utils\datastructures.py", line 78, in __getitem__
    list_ = super().__getitem__(key)
KeyError: 'id'

During handling of the above exception, another exception occurred:

Traceback (most recent call last):
  File "C:\dev\py\web3\lib\site-packages\django\core\handlers\exception.py", line 34, in inner
    response = get_response(request)
  File "C:\dev\py\web3\lib\site-packages\django\core\handlers\base.py", line 115, in _get_response
    response = self.process_exception_by_middleware(e, request)
  File "C:\dev\py\web3\lib\site-packages\django\core\handlers\base.py", line 113, in _get_response
    response = wrapped_callback(request, *callback_args, **callback_kwargs)
  File "C:\dev\py\web3\mysite\rethit\views.py", line 26, in upvote
    post_id = int(request.POST['id'])
  File "C:\dev\py\web3\lib\site-packages\django\utils\datastructures.py", line 80, in __getitem__
    raise MultiValueDictKeyError(key)
django.utils.datastructures.MultiValueDictKeyError: 'id'
"GET /upvote?id=2 HTTP/1.1" 500 16319
Internal Server Error: /upvote
Traceback (most recent call last):
  File "C:\dev\py\web3\lib\site-packages\django\utils\datastructures.py", line 78, in __getitem__
    list_ = super().__getitem__(key)
KeyError: 'id'

During handling of the above exception, another exception occurred:

Traceback (most recent call last):
  File "C:\dev\py\web3\lib\site-packages\django\core\handlers\exception.py", line 34, in inner
    response = get_response(request)
  File "C:\dev\py\web3\lib\site-packages\django\core\handlers\base.py", line 115, in _get_response
    response = self.process_exception_by_middleware(e, request)
  File "C:\dev\py\web3\lib\site-packages\django\core\handlers\base.py", line 113, in _get_response
    response = wrapped_callback(request, *callback_args, **callback_kwargs)
  File "C:\dev\py\web3\mysite\rethit\views.py", line 26, in upvote
    post_id = int(request.POST['id'])
  File "C:\dev\py\web3\lib\site-packages\django\utils\datastructures.py", line 80, in __getitem__
    raise MultiValueDictKeyError(key)
django.utils.datastructures.MultiValueDictKeyError: 'id'
"GET /upvote?id=1 HTTP/1.1" 500 16319
Internal Server Error: /upvote
Traceback (most recent call last):
  File "C:\dev\py\web3\lib\site-packages\django\utils\datastructures.py", line 78, in __getitem__
    list_ = super().__getitem__(key)
KeyError: 'id'

During handling of the above exception, another exception occurred:

Traceback (most recent call last):
  File "C:\dev\py\web3\lib\site-packages\django\core\handlers\exception.py", line 34, in inner
    response = get_response(request)
  File "C:\dev\py\web3\lib\site-packages\django\core\handlers\base.py", line 115, in _get_response
    response = self.process_exception_by_middleware(e, request)
  File "C:\dev\py\web3\lib\site-packages\django\core\handlers\base.py", line 113, in _get_response
    response = wrapped_callback(request, *callback_args, **callback_kwargs)
  File "C:\dev\py\web3\mysite\rethit\views.py", line 26, in upvote
    post_id = int(request.POST['id'])
  File "C:\dev\py\web3\lib\site-packages\django\utils\datastructures.py", line 80, in __getitem__
    raise MultiValueDictKeyError(key)
django.utils.datastructures.MultiValueDictKeyError: 'id'
"GET /upvote?id=1 HTTP/1.1" 500 16319
Internal Server Error: /upvote
Traceback (most recent call last):
  File "C:\dev\py\web3\lib\site-packages\django\utils\datastructures.py", line 78, in __getitem__
    list_ = super().__getitem__(key)
KeyError: 'id'

During handling of the above exception, another exception occurred:

Traceback (most recent call last):
  File "C:\dev\py\web3\lib\site-packages\django\core\handlers\exception.py", line 34, in inner
    response = get_response(request)
  File "C:\dev\py\web3\lib\site-packages\django\core\handlers\base.py", line 115, in _get_response
    response = self.process_exception_by_middleware(e, request)
  File "C:\dev\py\web3\lib\site-packages\django\core\handlers\base.py", line 113, in _get_response
    response = wrapped_callback(request, *callback_args, **callback_kwargs)
  File "C:\dev\py\web3\mysite\rethit\views.py", line 26, in upvote
    post_id = int(request.POST['id'])
  File "C:\dev\py\web3\lib\site-packages\django\utils\datastructures.py", line 80, in __getitem__
    raise MultiValueDictKeyError(key)
django.utils.datastructures.MultiValueDictKeyError: 'id'
"GET /upvote?id=1 HTTP/1.1" 500 16319
Internal Server Error: /upvote
Traceback (most recent call last):
  File "C:\dev\py\web3\lib\site-packages\django\utils\datastructures.py", line 78, in __getitem__
    list_ = super().__getitem__(key)
KeyError: 'id'

During handling of the above exception, another exception occurred:

Traceback (most recent call last):
  File "C:\dev\py\web3\lib\site-packages\django\core\handlers\exception.py", line 34, in inner
    response = get_response(request)
  File "C:\dev\py\web3\lib\site-packages\django\core\handlers\base.py", line 115, in _get_response
    response = self.process_exception_by_middleware(e, request)
  File "C:\dev\py\web3\lib\site-packages\django\core\handlers\base.py", line 113, in _get_response
    response = wrapped_callback(request, *callback_args, **callback_kwargs)
  File "C:\dev\py\web3\mysite\rethit\views.py", line 26, in upvote
    post_id = int(request.POST['id'])
  File "C:\dev\py\web3\lib\site-packages\django\utils\datastructures.py", line 80, in __getitem__
    raise MultiValueDictKeyError(key)
django.utils.datastructures.MultiValueDictKeyError: 'id'
"GET /upvote?id=1 HTTP/1.1" 500 16319
Internal Server Error: /upvote
Traceback (most recent call last):
  File "C:\dev\py\web3\lib\site-packages\django\utils\datastructures.py", line 78, in __getitem__
    list_ = super().__getitem__(key)
KeyError: 'id'

During handling of the above exception, another exception occurred:

Traceback (most recent call last):
  File "C:\dev\py\web3\lib\site-packages\django\core\handlers\exception.py", line 34, in inner
    response = get_response(request)
  File "C:\dev\py\web3\lib\site-packages\django\core\handlers\base.py", line 115, in _get_response
    response = self.process_exception_by_middleware(e, request)
  File "C:\dev\py\web3\lib\site-packages\django\core\handlers\base.py", line 113, in _get_response
    response = wrapped_callback(request, *callback_args, **callback_kwargs)
  File "C:\dev\py\web3\mysite\rethit\views.py", line 26, in upvote
    post_id = int(request.POST['id'])
  File "C:\dev\py\web3\lib\site-packages\django\utils\datastructures.py", line 80, in __getitem__
    raise MultiValueDictKeyError(key)
django.utils.datastructures.MultiValueDictKeyError: 'id'
"GET /upvote?id=1 HTTP/1.1" 500 16319
Internal Server Error: /upvote
Traceback (most recent call last):
  File "C:\dev\py\web3\lib\site-packages\django\utils\datastructures.py", line 78, in __getitem__
    list_ = super().__getitem__(key)
KeyError: 'id'

During handling of the above exception, another exception occurred:

Traceback (most recent call last):
  File "C:\dev\py\web3\lib\site-packages\django\core\handlers\exception.py", line 34, in inner
    response = get_response(request)
  File "C:\dev\py\web3\lib\site-packages\django\core\handlers\base.py", line 115, in _get_response
    response = self.process_exception_by_middleware(e, request)
  File "C:\dev\py\web3\lib\site-packages\django\core\handlers\base.py", line 113, in _get_response
    response = wrapped_callback(request, *callback_args, **callback_kwargs)
  File "C:\dev\py\web3\mysite\rethit\views.py", line 26, in upvote
    post_id = int(request.POST['id'])
  File "C:\dev\py\web3\lib\site-packages\django\utils\datastructures.py", line 80, in __getitem__
    raise MultiValueDictKeyError(key)
django.utils.datastructures.MultiValueDictKeyError: 'id'
"GET /upvote?id=2 HTTP/1.1" 500 16319
Internal Server Error: /upvote
Traceback (most recent call last):
  File "C:\dev\py\web3\lib\site-packages\django\utils\datastructures.py", line 78, in __getitem__
    list_ = super().__getitem__(key)
KeyError: 'id'

During handling of the above exception, another exception occurred:

Traceback (most recent call last):
  File "C:\dev\py\web3\lib\site-packages\django\core\handlers\exception.py", line 34, in inner
    response = get_response(request)
  File "C:\dev\py\web3\lib\site-packages\django\core\handlers\base.py", line 115, in _get_response
    response = self.process_exception_by_middleware(e, request)
  File "C:\dev\py\web3\lib\site-packages\django\core\handlers\base.py", line 113, in _get_response
    response = wrapped_callback(request, *callback_args, **callback_kwargs)
  File "C:\dev\py\web3\mysite\rethit\views.py", line 26, in upvote
    post_id = int(request.POST['id'])
  File "C:\dev\py\web3\lib\site-packages\django\utils\datastructures.py", line 80, in __getitem__
    raise MultiValueDictKeyError(key)
django.utils.datastructures.MultiValueDictKeyError: 'id'
"GET /upvote?id=2 HTTP/1.1" 500 16319
Internal Server Error: /upvote
Traceback (most recent call last):
  File "C:\dev\py\web3\lib\site-packages\django\utils\datastructures.py", line 78, in __getitem__
    list_ = super().__getitem__(key)
KeyError: 'id'

During handling of the above exception, another exception occurred:

Traceback (most recent call last):
  File "C:\dev\py\web3\lib\site-packages\django\core\handlers\exception.py", line 34, in inner
    response = get_response(request)
  File "C:\dev\py\web3\lib\site-packages\django\core\handlers\base.py", line 115, in _get_response
    response = self.process_exception_by_middleware(e, request)
  File "C:\dev\py\web3\lib\site-packages\django\core\handlers\base.py", line 113, in _get_response
    response = wrapped_callback(request, *callback_args, **callback_kwargs)
  File "C:\dev\py\web3\mysite\rethit\views.py", line 26, in upvote
    post_id = int(request.POST['id'])
  File "C:\dev\py\web3\lib\site-packages\django\utils\datastructures.py", line 80, in __getitem__
    raise MultiValueDictKeyError(key)
django.utils.datastructures.MultiValueDictKeyError: 'id'
"GET /upvote?id=2 HTTP/1.1" 500 16319
Internal Server Error: /upvote
Traceback (most recent call last):
  File "C:\dev\py\web3\lib\site-packages\django\utils\datastructures.py", line 78, in __getitem__
    list_ = super().__getitem__(key)
KeyError: 'id'

During handling of the above exception, another exception occurred:

Traceback (most recent call last):
  File "C:\dev\py\web3\lib\site-packages\django\core\handlers\exception.py", line 34, in inner
    response = get_response(request)
  File "C:\dev\py\web3\lib\site-packages\django\core\handlers\base.py", line 115, in _get_response
    response = self.process_exception_by_middleware(e, request)
  File "C:\dev\py\web3\lib\site-packages\django\core\handlers\base.py", line 113, in _get_response
    response = wrapped_callback(request, *callback_args, **callback_kwargs)
  File "C:\dev\py\web3\mysite\rethit\views.py", line 26, in upvote
    post_id = int(request.POST['id'])
  File "C:\dev\py\web3\lib\site-packages\django\utils\datastructures.py", line 80, in __getitem__
    raise MultiValueDictKeyError(key)
django.utils.datastructures.MultiValueDictKeyError: 'id'
"GET /upvote?id=3 HTTP/1.1" 500 16319
Internal Server Error: /upvote
Traceback (most recent call last):
  File "C:\dev\py\web3\lib\site-packages\django\utils\datastructures.py", line 78, in __getitem__
    list_ = super().__getitem__(key)
KeyError: 'id'

During handling of the above exception, another exception occurred:

Traceback (most recent call last):
  File "C:\dev\py\web3\lib\site-packages\django\core\handlers\exception.py", line 34, in inner
    response = get_response(request)
  File "C:\dev\py\web3\lib\site-packages\django\core\handlers\base.py", line 115, in _get_response
    response = self.process_exception_by_middleware(e, request)
  File "C:\dev\py\web3\lib\site-packages\django\core\handlers\base.py", line 113, in _get_response
    response = wrapped_callback(request, *callback_args, **callback_kwargs)
  File "C:\dev\py\web3\mysite\rethit\views.py", line 26, in upvote
    post_id = int(request.POST['id'])
  File "C:\dev\py\web3\lib\site-packages\django\utils\datastructures.py", line 80, in __getitem__
    raise MultiValueDictKeyError(key)
django.utils.datastructures.MultiValueDictKeyError: 'id'
"GET /upvote?id=3 HTTP/1.1" 500 16319
Internal Server Error: /upvote
Traceback (most recent call last):
  File "C:\dev\py\web3\lib\site-packages\django\utils\datastructures.py", line 78, in __getitem__
    list_ = super().__getitem__(key)
KeyError: 'id'

During handling of the above exception, another exception occurred:

Traceback (most recent call last):
  File "C:\dev\py\web3\lib\site-packages\django\core\handlers\exception.py", line 34, in inner
    response = get_response(request)
  File "C:\dev\py\web3\lib\site-packages\django\core\handlers\base.py", line 115, in _get_response
    response = self.process_exception_by_middleware(e, request)
  File "C:\dev\py\web3\lib\site-packages\django\core\handlers\base.py", line 113, in _get_response
    response = wrapped_callback(request, *callback_args, **callback_kwargs)
  File "C:\dev\py\web3\mysite\rethit\views.py", line 26, in upvote
    post_id = int(request.POST['id'])
  File "C:\dev\py\web3\lib\site-packages\django\utils\datastructures.py", line 80, in __getitem__
    raise MultiValueDictKeyError(key)
django.utils.datastructures.MultiValueDictKeyError: 'id'
"GET /upvote?id=3 HTTP/1.1" 500 16319
C:\dev\py\web3\mysite\rethit\views.py changed, reloading.
Watching for file changes with StatReloader
"GET / HTTP/1.1" 200 2810
"GET /upvote?id=3 HTTP/1.1" 200 1
"GET /upvote?id=1 HTTP/1.1" 200 1
"GET / HTTP/1.1" 200 2750
"GET /upvote?id=3 HTTP/1.1" 200 1
"GET /upvote?id=2 HTTP/1.1" 200 1
"GET /downvote?id=1 HTTP/1.1" 200 1
"GET /downvote?id=2 HTTP/1.1" 200 1
"GET /downvote?id=3 HTTP/1.1" 200 1
"GET /downvote?id=3 HTTP/1.1" 200 1
"GET /downvote?id=3 HTTP/1.1" 200 1
"GET /downvote?id=3 HTTP/1.1" 200 1
"GET /downvote?id=3 HTTP/1.1" 200 2
"GET /downvote?id=3 HTTP/1.1" 200 2
"GET /downvote?id=3 HTTP/1.1" 200 2
"GET /downvote?id=3 HTTP/1.1" 200 2
"GET /downvote?id=3 HTTP/1.1" 200 2
"GET /downvote?id=3 HTTP/1.1" 200 2
"GET /downvote?id=3 HTTP/1.1" 200 2
"GET /downvote?id=3 HTTP/1.1" 200 2
"GET /downvote?id=3 HTTP/1.1" 200 2
"GET /downvote?id=3 HTTP/1.1" 200 3
"GET /downvote?id=3 HTTP/1.1" 200 3
"GET /downvote?id=3 HTTP/1.1" 200 3
"GET /upvote?id=3 HTTP/1.1" 200 3
"GET /upvote?id=3 HTTP/1.1" 200 3
"GET /upvote?id=3 HTTP/1.1" 200 2
"GET /upvote?id=3 HTTP/1.1" 200 2
"GET /upvote?id=3 HTTP/1.1" 200 2
"GET /upvote?id=3 HTTP/1.1" 200 2
"GET /upvote?id=3 HTTP/1.1" 200 2
"GET /upvote?id=3 HTTP/1.1" 200 2
"GET /upvote?id=3 HTTP/1.1" 200 2
"GET /upvote?id=3 HTTP/1.1" 200 2
"GET /upvote?id=3 HTTP/1.1" 200 1
"GET /upvote?id=3 HTTP/1.1" 200 1
"GET /upvote?id=3 HTTP/1.1" 200 1
"GET /upvote?id=3 HTTP/1.1" 200 1
"GET /upvote?id=3 HTTP/1.1" 200 1
